<?xml version="1.0" encoding="utf-8"?>
<!-- This URDF was automatically created by SolidWorks to URDF Exporter! Originally created by Stephen Brawner (brawner@gmail.com) 
     Commit Version: 1.6.0-4-g7f85cfe  Build Version: 1.6.7995.38578
     For more information, please see http://wiki.ros.org/sw_urdf_exporter -->
<robot
  name="final">
  <link
    name="base_link">
    <inertial>
      <origin
        xyz="-0.0080629 0.011439 -0.071869"
        rpy="0 0 0" />
      <mass
        value="0.48171" />
      <inertia
        ixx="0.0096804"
        ixy="-2.5984E-09"
        ixz="-6.4002E-06"
        iyy="0.0031976"
        iyz="6.1207E-09"
        izz="0.0067781" />
    </inertial>
    <visual>
      <origin
        xyz="0 0 0"
        rpy="0 0 0" />
      <geometry>
        <mesh
          filename="file:///home/nava/ros2_ws/src/modelo_robot/meshes/base_link.STL" />
      </geometry>
      <material
        name="">
        <color
          rgba="0.79216 0.81961 0.93333 1" />
      </material>
    </visual>
    <collision>
      <origin
        xyz="0 0 0"
        rpy="0 0 0" />
      <geometry>
        <mesh
          filename="file:///home/nava/ros2_ws/src/modelo_robot/meshes/base_link.STL" />
      </geometry>
    </collision>
  </link>
  <link
    name="movil_Link">
    <inertial>
      <origin
        xyz="1.3509E-06 0.0018796 -0.0076872"
        rpy="0 0 0" />
      <mass
        value="0.077463" />
      <inertia
        ixx="6.1041E-05"
        ixy="-3.9804E-09"
        ixz="9.766E-10"
        iyy="6.1557E-05"
        iyz="3.8412E-06"
        izz="1.4866E-05" />
    </inertial>
    <visual>
      <origin
        xyz="0 0 0"
        rpy="0 0 0" />
      <geometry>
        <mesh
          filename="file:///home/nava/ros2_ws/src/modelo_robot/meshes/movil_Link.STL" />
      </geometry>
      <material
        name="">
        <color
          rgba="0.79216 0.81961 0.93333 1" />
      </material>
    </visual>
    <collision>
      <origin
        xyz="0 0 0"
        rpy="0 0 0" />
      <geometry>
        <mesh
          filename="file:///home/nava/ros2_ws/src/modelo_robot/meshes/movil_Link.STL" />
      </geometry>
    </collision>
  </link>
  <joint
    name="movil_joint"
    type="prismatic">
    <origin
      xyz="-0.0048478 0.19467 0.005"
      rpy="1.5708 0 -1.5708" />
    <parent
      link="base_link" />
    <child
      link="movil_Link" />
    <axis
      xyz="1 0 0" />
    <limit
      lower="0"
      upper="0.4"
      effort="0"
      velocity="0" />
    <calibration
      rising="0"
      falling="0" />
    <dynamics
      damping="0"
      friction="0.1" />
  </joint>
  <link
    name="pendulo_Link">
    <inertial>
      <origin
        xyz="-2.3098E-09 0.17205 -0.006"
        rpy="0 0 0" />
      <mass
        value="0.10222" />
      <inertia
        ixx="0.0015673"
        ixy="-5.9689E-11"
        ixz="1.1423E-11"
        iyy="6.9378E-07"
        iyz="2.9552E-10"
        izz="0.0015674" />
    </inertial>
    <visual>
      <origin
        xyz="0 0 0"
        rpy="0 0 0" />
      <geometry>
        <mesh
          filename="file:///home/nava/ros2_ws/src/modelo_robot/meshes/pendulo_Link.STL" />
      </geometry>
      <material
        name="">
        <color
          rgba="0.77647 0.75686 0.73725 1" />
      </material>
    </visual>
    <collision>
      <origin
        xyz="0 0 0"
        rpy="0 0 0" />
      <geometry>
        <mesh
          filename="file:///home/nava/ros2_ws/src/modelo_robot/meshes/pendulo_Link.STL" />
      </geometry>
    </collision>
  </link>
  <joint
    name="pendulo_joint"
    type="continuous">
    <origin
      xyz="0 0.02 -0.0575"
      rpy="-3.1416 0 -0.34603" />
    <parent
      link="movil_Link" />
    <child
      link="pendulo_Link" />
    <axis
      xyz="0 0 1" />
    <calibration
      rising="0"
      falling="0" />
    <dynamics
      damping="0"
      friction="0.1" />
  </joint>
  <link
    name="masa_Link">
    <inertial>
      <origin
        xyz="1.7208E-14 0.00025864 -3.3307E-16"
        rpy="0 0 0" />
      <mass
        value="0.050997" />
      <inertia
        ixx="2.771E-06"
        ixy="-4.7646E-22"
        ixz="-1.3319E-22"
        iyy="2.8796E-06"
        iyz="1.0332E-22"
        izz="2.771E-06" />
    </inertial>
    <visual>
      <origin
        xyz="0 0 0"
        rpy="0 0 0" />
      <geometry>
        <mesh
          filename="file:///home/nava/ros2_ws/src/modelo_robot/meshes/masa_Link.STL" />
      </geometry>
      <material
        name="">
        <color
          rgba="0.77647 0.75686 0.73725 1" />
      </material>
    </visual>
    <collision>
      <origin
        xyz="0 0 0"
        rpy="0 0 0" />
      <geometry>
        <mesh
          filename="file:///home/nava/ros2_ws/src/modelo_robot/meshes/masa_Link.STL" />
      </geometry>
    </collision>
  </link>
  <joint
    name="masa_joint"
    type="fixed">
    <origin
      xyz="0 0.3967 -0.006"
      rpy="-3.1416 0 3.1416" />
    <parent
      link="pendulo_Link" />
    <child
      link="masa_Link" />
    <axis
      xyz="0 0 0" />
    <calibration
      rising="0"
      falling="0" />
    <dynamics
      damping="0"
      friction="0.1" />
  </joint>
</robot>